Workbook
Name BEDS_CARROT: Optimization!$B$6
Name BEDS_MESCLUN: Optimization!$B$7
Name BEDS_TOMATO: Optimization!$B$5
Name BLENDED_RATE: CostStructure!$B$19
Name CONSTRAINTS_ALL: Optimization!$D$25
Name DIM_PCT_CAR: Inputs!$C$10
Name DIM_PCT_MES: Inputs!$D$10
Name DIM_PCT_TOM: Inputs!$B$10
Name FARMER_FIELD_HRS: Inputs!$B$18
Name FARMER_HRS_USED: CostStructure!$B$11
Name FARMER_LABOR_COST: CostStructure!$B$16
Name FARMER_RATE: Inputs!$B$20
Name FARMER_SALARY: Inputs!$B$17
Name FARMER_SEASON_HRS: Inputs!$B$19
Name FERTILIZER_COST: CostStructure!$B$30
Name FERTILIZER_PER_BED_CAR: Inputs!$C$9
Name FERTILIZER_PER_BED_MES: Inputs!$D$9
Name FERTILIZER_PER_BED_TOM: Inputs!$B$9
Name FIXED_COSTS: Inputs!$B$15
Name HAND_CHECK_Q1: CostStructure!$B$37
Name HRS_PER_BED_WEEK_CAR: Inputs!$C$8
Name HRS_PER_BED_WEEK_MES: Inputs!$D$8
Name HRS_PER_BED_WEEK_TOM: Inputs!$B$8
Name MAX_BEDS_CAR: Inputs!$C$6
Name MAX_BEDS_MES: Inputs!$D$6
Name MAX_BEDS_TOM: Inputs!$B$6
Name MAX_TEMPS: Inputs!$B$24
Name PMC_CAR: MCSchedules!$P$29
Name PMC_MES: MCSchedules!$Z$39
Name PMC_TOM: MCSchedules!$F$29
Name PRICE_PER_BED_CAR: Inputs!$C$7
Name PRICE_PER_BED_MES: Inputs!$D$7
Name PRICE_PER_BED_TOM: Inputs!$B$7
Name SEASON_PROFIT: CostStructure!$B$34
Name SEASON_REVENUE: CostStructure!$B$29
Name SHADOW_CAR: Optimization!$J$61
Name SHADOW_MES: Optimization!$J$62
Name TEMP_COST_EACH: Inputs!$B$21
Name TEMP_HRS_EACH: Inputs!$B$22
Name TEMP_HRS_USED: CostStructure!$B$12
Name TEMP_LABOR_COST: CostStructure!$B$17
Name TEMP_RATE: Inputs!$B$23
Name TEMPS_REQUIRED: CostStructure!$B$13
Name TOTAL_BED_CAP: Inputs!$B$16
Name TOTAL_COST_SEASON: CostStructure!$B$32
Name TOTAL_LABOR_COST: CostStructure!$B$18
Name TOTAL_LABOR_HRS: CostStructure!$B$8
Name WEEKS: Inputs!$B$14

Sheet Inputs
A1: Marginal Analysis Model — Inputs
A2: Every value below is a named range. Blue = hardcoded input from the case. Black = derived.
A4: Per-crop inputs
A5: Name | B5: Tomatoes | C5: Carrots | D5: Mesclun | E5: Unit | F5: Source
A6: MAX_BEDS | B6: 20 | C6: 20 | D6: 30 | E6: beds | F6: Case scenario table
A7: PRICE_PER_BED | B7: 8800 | C7: 2094 | D7: 2700 | E7: $ per bed per season | F7: Case scenario table — "Price $/bed"
A8: HRS_PER_BED_WEEK | B8: 2.5 | C8: 0.83333333 | D8: 1.25 | E8: hours per bed per week | F8: Case scenario; carrots shown as 0.833, stored as 5/6
A9: FERTILIZER_PER_BED | B9: 880 | C9: 440 | D9: 880 | E9: $ per bed | F9: Case scenario table
A10: DIM_PCT | B10: 0.1 | C10: 0.025 | D10: 0.0125 | E10: fraction per added bed | F10: Case scenario — "Diminishing returns"
A12: Farm-level inputs
A13: Name | B13: Value | E13: Unit | F13: Source
A14: WEEKS | B14: 36 | E14: weeks per season | F14: Case scenario
A15: FIXED_COSTS | B15: 20000 | E15: $ per season | F15: Case scenario
A16: TOTAL_BED_CAP | B16: 64 | E16: beds (16 beds x 4 plots) | F16: Case scenario
A17: FARMER_SALARY | B17: 50000 | E17: $ per season | F17: Case scenario
A18: FARMER_FIELD_HRS | B18: 720 | E18: hours per season | F18: Case scenario — half her time in the field
A19: FARMER_SEASON_HRS | B19: =2*FARMER_FIELD_HRS -> 1440 | E19: hours per season | F19: Derived: 2 x FARMER_FIELD_HRS
A20: FARMER_RATE | B20: =FARMER_SALARY/FARMER_SEASON_HRS -> 34.722222 | E20: $ per hour | F20: Derived: FARMER_SALARY / FARMER_SEASON_HRS (the case's implied $34.72)
A21: TEMP_COST_EACH | B21: 25000 | E21: $ per worker per season | F21: Case scenario
A22: TEMP_HRS_EACH | B22: 1440 | E22: hours per worker per season | F22: Case scenario
A23: TEMP_RATE | B23: =TEMP_COST_EACH/TEMP_HRS_EACH -> 17.361111 | E23: $ per hour | F23: Derived: TEMP_COST_EACH / TEMP_HRS_EACH (the case's $17.36)
A24: MAX_TEMPS | B24: 4 | E24: workers | F24: Case scenario
A26: Legend
A27: Blue text = hardcoded input from the case scenario. Do not edit unless the case changes.
A28: Black text = formula. Green text = link to another sheet. Yellow fill = cell you set.
A29: The three bed counts are the only cells you change by hand; they live on the Optimization sheet.

Sheet Optimization
A1: Optimization
A2: Enter the Solver settings below by hand — Data > Solver. Five constraints, about two minutes.
A4: Decision variables — Solver changing cells | B4: Beds (change these) | C4: Cap
A5: Tomato beds | B5: 10 | C5: =MAX_BEDS_TOM -> 20 | E5: Integer, at least 0, at most the cap
A6: Carrot beds | B6: 20 | C6: =MAX_BEDS_CAR -> 20 | E6: Integer, at least 0, at most the cap
A7: Mesclun beds | B7: 30 | C7: =MAX_BEDS_MES -> 30 | E7: Integer, at least 0, at most the cap
A9: Constraint quantities — Solver constrains these
A10: Total beds planted | B10: =SUM(B5:B7) -> 60 | C10: =TOTAL_BED_CAP -> 64 | E10: At most 64
A11: Temporary hours needed | B11: =TEMP_HRS_USED -> 4557.2161 | C11: =MAX_TEMPS*TEMP_HRS_EACH -> 5760 | E11: At most 4 workers x 1,440 hours = 5,760. Equivalent to "at most 4 workers", but smooth.
E12: ROUNDUP is deliberately kept OUT of the Solver constraint: GRG Nonlinear assumes smooth
A13: Temporary workers required (reported) | B13: =TEMPS_REQUIRED -> 4 | C13: =MAX_TEMPS -> 4 | E13: functions, and a step function here makes it stall. The headcount is still reported below.
A15: Objective — Solver maximizes this cell
A16: Season profit | B16: =SEASON_PROFIT -> 42761.665
A18: Constraint checks
A19: Constraint | B19: Value | C19: Limit | D19: Status
A20: Tomato beds at most cap | B20: =B5 -> 10 | C20: =C5 -> 20 | D20: =IF(B20<=C20,"PASS","FAIL") -> PASS
A21: Carrot beds at most cap | B21: =B6 -> 20 | C21: =C6 -> 20 | D21: =IF(B21<=C21,"PASS","FAIL") -> PASS
A22: Mesclun beds at most cap | B22: =B7 -> 30 | C22: =C7 -> 30 | D22: =IF(B22<=C22,"PASS","FAIL") -> PASS
A23: Total beds at most 64 | B23: =B10 -> 60 | C23: =C10 -> 64 | D23: =IF(B23<=C23,"PASS","FAIL") -> PASS
A24: Temp workers at most 4 | B24: =B13 -> 4 | C24: =C13 -> 4 | D24: =IF(B24<=C24,"PASS","FAIL") -> PASS
A25: All constraints | D25: =IF(COUNTIF(D20:D24,"PASS")=5,"PASS","FAIL") -> PASS
A27: How to run the audit
A28: 1. Set B5:B7 to 0, 0, 0. Data > Solver > Solve. Record the answer on the Checks sheet.
A29: 2. Set B5:B7 to 20, 0, 0. Data > Solver > Solve again. Record that answer too.
A30: 3. If the two runs disagree, that is a finding — GRG Nonlinear stops at the first summit it reaches.
A31: 4. Read the Checks sheet: twelve rules, each PASS or FAIL.
A33: If Solver is missing from the Data ribbon: File > Options > Add-ins > Manage: Excel Add-ins > Go >
A34: tick Solver Add-in. On Mac: Tools > Excel Add-ins > tick Solver.
A36: Solver settings — type these into Data > Solver
A37: Set Objective | B37: $B$16
A38: To | B38: Max
A39: By Changing Variable Cells | B39: $B$5:$B$7
A41: Subject to the Constraints — click Add for each
A42: Cell Reference | B42: Relation | C42: Constraint
A43: $B$5:$B$7 | B43: int | C43: integer
A44: $B$5:$B$7 | B44: <= | C44: $C$5:$C$7
A45: $B$10 | B45: <= | C45: $C$10
A46: $B$11 | B46: <= | C46: $C$11
A48: Select a Solving Method: GRG Nonlinear.
A49: Tick "Make Unconstrained Variables Non-Negative".
...

Sheet CostStructure
A1: Cost structure at the current bed counts
A2: Everything here is a formula. Change the bed counts on the Optimization sheet and these follow.
A4: Labor hours — 3.1 and 3.5
A5: Tomato labor hours | B5: =BEDS_TOMATO*HRS_PER_BED_WEEK_TOM*WEEKS*(1+DIM_PCT_TOM)^BEDS_TOMATO -> 2334.3682 | E5: q x hrs/bed-week x weeks x (1+dim)^q
A6: Carrot labor hours | B6: =BEDS_CARROT*HRS_PER_BED_WEEK_CAR*WEEKS*(1+DIM_PCT_CAR)^BEDS_CARROT -> 983.16986
A7: Mesclun labor hours | B7: =BEDS_MESCLUN*HRS_PER_BED_WEEK_MES*WEEKS*(1+DIM_PCT_MES)^BEDS_MESCLUN -> 1959.678
A8: TOTAL_LABOR_HRS | B8: =SUM(B5:B7) -> 5277.2161 | E8: all hours, all three crops
A10: Who covers the hours — 3.5
A11: FARMER_HRS_USED | B11: =MIN(TOTAL_LABOR_HRS,FARMER_FIELD_HRS) -> 720 | E11: the farmer is consumed first, always
A12: TEMP_HRS_USED | B12: =MAX(0,TOTAL_LABOR_HRS-FARMER_FIELD_HRS) -> 4557.2161 | E12: temps cover only the remainder
A13: TEMPS_REQUIRED | B13: =ROUNDUP(TEMP_HRS_USED/TEMP_HRS_EACH,0) -> 4 | E13: headcount for the cap only; cost never uses it
A15: Labor cost — 3.6, 3.7, 3.9
A16: FARMER_LABOR_COST | B16: =FARMER_HRS_USED*FARMER_RATE -> 25000 | E16: field hours only; the other half of her salary is not crop labor
A17: TEMP_LABOR_COST | B17: =TEMP_HRS_USED*TEMP_RATE -> 79118.335 | E17: hours actually used, not a lump sum per worker
A18: TOTAL_LABOR_COST | B18: =FARMER_LABOR_COST+TEMP_LABOR_COST -> 104118.34
A19: BLENDED_RATE | B19: =IF(TOTAL_LABOR_HRS=0,0,TOTAL_LABOR_COST/TOTAL_LABOR_HRS) -> 19.729784 | E19: total labor dollars / total labor hours
A21: Labor allocated to crops at the blended rate — 3.9
A22: Reporting only. This allocation is never added on top of TOTAL_LABOR_COST.
A23: Tomato labor cost | B23: =B5*BLENDED_RATE -> 46056.581
A24: Carrot labor cost | B24: =B6*BLENDED_RATE -> 19397.729
A25: Mesclun labor cost | B25: =B7*BLENDED_RATE -> 38664.025
A26: Check: allocation equals total | B26: =SUM(B23:B25) -> 104118.34 | E26: must equal TOTAL_LABOR_COST
A28: Revenue, fertilizer, profit — 3.3, 3.4, 3.11
A29: SEASON_REVENUE | B29: =BEDS_TOMATO*PRICE_PER_BED_TOM+BEDS_CARROT*PRICE_PER_BED_CAR+BEDS_MESCLUN*PRICE_PER_BED_MES -> 210880 | E29: price per bed is constant — the farm is a price taker
A30: FERTILIZER_COST | B30: =BEDS_TOMATO*FERTILIZER_PER_BED_TOM+BEDS_CARROT*FERTILIZER_PER_BED_CAR+BEDS_MESCLUN*FERTILIZER_PER_BED_MES -> 44000 | E30: linear in beds
A31: Fixed costs | B31: =FIXED_COSTS -> 20000 | E31: contains no part of FARMER_SALARY
A32: TOTAL_COST | B32: =FERTILIZER_COST+TOTAL_LABOR_COST+FIXED_COSTS -> 168118.34
A34: SEASON_PROFIT | B34: =SEASON_REVENUE-FERTILIZER_COST-TOTAL_LABOR_COST-FIXED_COSTS -> 42761.665 | E34: labor counted once
A36: Hand check — 3.1 at q = 1
A37: LABOR_HRS(1) for tomatoes | B37: =1*HRS_PER_BED_WEEK_TOM*WEEKS*(1+DIM_PCT_TOM)^1 -> 99 | E37: 1 x 2.50 x 36 x 1.10 = 99 hours

Sheet MCSchedules
A1: Standalone marginal cost schedules — 3.10
A2: Standalone: the other two crops are held at ZERO beds, so each schedule shows that crop alone.
A3: Labor cost follows 3.5-3.7: the farmer's 720 field hours first, then temps. Fixed costs are excluded — they cancel in the subtraction.
A5: Tomatoes | K5: Carrots | U5: Mesclun
A6: q | B6: Labor hours | C6: Labor cost | D6: Fertilizer | E6: Total cost | F6: Marginal cost | G6: Price per bed | H6: MC <= P | I6: Run of MC <= P | K6: q | L6: Labor hours | M6: Labor cost | N6: Fertilizer | O6: Total cost | P6: Marginal cost | Q6: Price per bed | R6: MC <= P | S6: Run of MC <= P | U6: q | V6: Labor hours | W6: Labor cost | X6: Fertilizer | Y6: Total cost | Z6: Marginal cost | AA6: Price per bed | AB6: MC <= P | AC6: Run of MC <= P
A7: 0 | B7: =A7*HRS_PER_BED_WEEK_TOM*WEEKS*(1+DIM_PCT_TOM)^A7 -> 0 | C7: =MIN(B7,FARMER_FIELD_HRS)*FARMER_RATE+MAX(0,B7-FARMER_FIELD_HRS)*TEMP_RATE -> 0 | D7: =A7*FERTILIZER_PER_BED_TOM -> 0 | E7: =C7+D7 -> 0 | G7: =PRICE_PER_BED_TOM -> 8800 | I7: 1 | K7: 0 | L7: =K7*HRS_PER_BED_WEEK_CAR*WEEKS*(1+DIM_PCT_CAR)^K7 -> 0 | M7: =MIN(L7,FARMER_FIELD_HRS)*FARMER_RATE+MAX(0,L7-FARMER_FIELD_HRS)*TEMP_RATE -> 0 | N7: =K7*FERTILIZER_PER_BED_CAR -> 0 | O7: =M7+N7 -> 0 | Q7: =PRICE_PER_BED_CAR -> 2094 | S7: 1 | U7: 0 | V7: =U7*HRS_PER_BED_WEEK_MES*WEEKS*(1+DIM_PCT_MES)^U7 -> 0 | W7: =MIN(V7,FARMER_FIELD_HRS)*FARMER_RATE+MAX(0,V7-FARMER_FIELD_HRS)*TEMP_RATE -> 0 | X7: =U7*FERTILIZER_PER_BED_MES -> 0 | Y7: =W7+X7 -> 0 | AA7: =PRICE_PER_BED_MES -> 2700 | AC7: 1
A8: 1 | B8: =A8*HRS_PER_BED_WEEK_TOM*WEEKS*(1+DIM_PCT_TOM)^A8 -> 99 | C8: =MIN(B8,FARMER_FIELD_HRS)*FARMER_RATE+MAX(0,B8-FARMER_FIELD_HRS)*TEMP_RATE -> 3437.5 | D8: =A8*FERTILIZER_PER_BED_TOM -> 880 | E8: =C8+D8 -> 4317.5 | F8: =E8-E7 -> 4317.5 | G8: =PRICE_PER_BED_TOM -> 8800 | H8: =IF(F8<=PRICE_PER_BED_TOM,1,0) -> 1 | I8: =I7*H8 -> 1 | K8: 1 | L8: =K8*HRS_PER_BED_WEEK_CAR*WEEKS*(1+DIM_PCT_CAR)^K8 -> 30.75 | M8: =MIN(L8,FARMER_FIELD_HRS)*FARMER_RATE+MAX(0,L8-FARMER_FIELD_HRS)*TEMP_RATE -> 1067.7083 | N8: =K8*FERTILIZER_PER_BED_CAR -> 440 | O8: =M8+N8 -> 1507.7083 | P8: =O8-O7 -> 1507.7083 | Q8: =PRICE_PER_BED_CAR -> 2094 | R8: =IF(P8<=PRICE_PER_BED_CAR,1,0) -> 1 | S8: =S7*R8 -> 1 | U8: 1 | V8: =U8*HRS_PER_BED_WEEK_MES*WEEKS*(1+DIM_PCT_MES)^U8 -> 45.5625 | W8: =MIN(V8,FARMER_FIELD_HRS)*FARMER_RATE+MAX(0,V8-FARMER_FIELD_HRS)*TEMP_RATE -> 1582.0312 | X8: =U8*FERTILIZER_PER_BED_MES -> 880 | Y8: =W8+X8 -> 2462.0312 | Z8: =Y8-Y7 -> 2462.0312 | AA8: =PRICE_PER_BED_MES -> 2700 | AB8: =IF(Z8<=PRICE_PER_BED_MES,1,0) -> 1 | AC8: =AC7*AB8 -> 1
A9: 2 | B9: =A9*HRS_PER_BED_WEEK_TOM*WEEKS*(1+DIM_PCT_TOM)^A9 -> 217.8 | C9: =MIN(B9,FARMER_FIELD_HRS)*FARMER_RATE+MAX(0,B9-FARMER_FIELD_HRS)*TEMP_RATE -> 7562.5 | D9: =A9*FERTILIZER_PER_BED_TOM -> 1760 | E9: =C9+D9 -> 9322.5 | F9: =E9-E8 -> 5005 | G9: =PRICE_PER_BED_TOM -> 8800 | H9: =IF(F9<=PRICE_PER_BED_TOM,1,0) -> 1 | I9: =I8*H9 -> 1 | K9: 2 | L9: =K9*HRS_PER_BED_WEEK_CAR*WEEKS*(1+DIM_PCT_CAR)^K9 -> 63.0375 | M9: =MIN(L9,FARMER_FIELD_HRS)*FARMER_RATE+MAX(0,L9-FARMER_FIELD_HRS)*TEMP_RATE -> 2188.8021 | N9: =K9*FERTILIZER_PER_BED_CAR -> 880 | O9: =M9+N9 -> 3068.8021 | P9: =O9-O8 -> 1561.0937 | Q9: =PRICE_PER_BED_CAR -> 2094 | R9: =IF(P9<=PRICE_PER_BED_CAR,1,0) -> 1 | S9: =S8*R9 -> 1 | U9: 2 | V9: =U9*HRS_PER_BED_WEEK_MES*WEEKS*(1+DIM_PCT_MES)^U9 -> 92.264062 | W9: =MIN(V9,FARMER_FIELD_HRS)*FARMER_RATE+MAX(0,V9-FARMER_FIELD_HRS)*TEMP_RATE -> 3203.6133 | X9: =U9*FERTILIZER_PER_BED_MES -> 1760 | Y9: =W9+X9 -> 4963.6133 | Z9: =Y9-Y8 -> 2501.582 | AA9: =PRICE_PER_BED_MES -> 2700 | AB9: =IF(Z9<=PRICE_PER_BED_MES,1,0) -> 1 | AC9: =AC8*AB9 -> 1
A10: 3 | B10: =A10*HRS_PER_BED_WEEK_TOM*WEEKS*(1+DIM_PCT_TOM)^A10 -> 359.37 | C10: =MIN(B10,FARMER_FIELD_HRS)*FARMER_RATE+MAX(0,B10-FARMER_FIELD_HRS)*TEMP_RATE -> 12478.125 | D10: =A10*FERTILIZER_PER_BED_TOM -> 2640 | E10: =C10+D10 -> 15118.125 | F10: =E10-E9 -> 5795.625 | G10: =PRICE_PER_BED_TOM -> 8800 | H10: =IF(F10<=PRICE_PER_BED_TOM,1,0) -> 1 | I10: =I9*H10 -> 1 | K10: 3 | L10: =K10*HRS_PER_BED_WEEK_CAR*WEEKS*(1+DIM_PCT_CAR)^K10 -> 96.920156 | M10: =MIN(L10,FARMER_FIELD_HRS)*FARMER_RATE+MAX(0,L10-FARMER_FIELD_HRS)*TEMP_RATE -> 3365.2832 | N10: =K10*FERTILIZER_PER_BED_CAR -> 1320 | O10: =M10+N10 -> 4685.2832 | P10: =O10-O9 -> 1616.4811 | Q10: =PRICE_PER_BED_CAR -> 2094 | R10: =IF(P10<=PRICE_PER_BED_CAR,1,0) -> 1 | S10: =S9*R10 -> 1 | U10: 3 | V10: =U10*HRS_PER_BED_WEEK_MES*WEEKS*(1+DIM_PCT_MES)^U10 -> 140.12604 | W10: =MIN(V10,FARMER_FIELD_HRS)*FARMER_RATE+MAX(0,V10-FARMER_FIELD_HRS)*TEMP_RATE -> 4865.4877 | X10: =U10*FERTILIZER_PER_BED_MES -> 2640 | Y10: =W10+X10 -> 7505.4877 | Z10: =Y10-Y9 -> 2541.8744 | AA10: =PRICE_PER_BED_MES -> 2700 | AB10: =IF(Z10<=PRICE_PER_BED_MES,1,0) -> 1 | AC10: =AC9*AB10 -> 1
A11: 4 | B11: =A11*HRS_PER_BED_WEEK_TOM*WEEKS*(1+DIM_PCT_TOM)^A11 -> 527.076 | C11: =MIN(B11,FARMER_FIELD_HRS)*FARMER_RATE+MAX(0,B11-FARMER_FIELD_HRS)*TEMP_RATE -> 18301.25 | D11: =A11*FERTILIZER_PER_BED_TOM -> 3520 | E11: =C11+D11 -> 21821.25 | F11: =E11-E10 -> 6703.125 | G11: =PRICE_PER_BED_TOM -> 8800 | H11: =IF(F11<=PRICE_PER_BED_TOM,1,0) -> 1 | I11: =I10*H11 -> 1 | K11: 4 | L11: =K11*HRS_PER_BED_WEEK_CAR*WEEKS*(1+DIM_PCT_CAR)^K11 -> 132.45755 | M11: =MIN(L11,FARMER_FIELD_HRS)*FARMER_RATE+MAX(0,L11-FARMER_FIELD_HRS)*TEMP_RATE -> 4599.2204 | N11: =K11*FERTILIZER_PER_BED_CAR -> 1760 | O11: =M11+N11 -> 6359.2204 | P11: =O11-O10 -> 1673.9372 | Q11: =PRICE_PER_BED_CAR -> 2094 | R11: =IF(P11<=PRICE_PER_BED_CAR,1,0) -> 1 | S11: =S10*R11 -> 1 | U11: 4 | V11: =U11*HRS_PER_BED_WEEK_MES*WEEKS*(1+DIM_PCT_MES)^U11 -> 189.17016 | W11: =MIN(V11,FARMER_FIELD_HRS)*FARMER_RATE+MAX(0,V11-FARMER_FIELD_HRS)*TEMP_RATE -> 6568.4084 | X11: =U11*FERTILIZER_PER_BED_MES -> 3520 | Y11: =W11+X11 -> 10088.408 | Z11: =Y11-Y10 -> 2582.9207 | AA11: =PRICE_PER_BED_MES -> 2700 | AB11: =IF(Z11<=PRICE_PER_BED_MES,1,0) -> 1 | AC11: =AC10*AB11 -> 1
A12: 5 | B12: =A12*HRS_PER_BED_WEEK_TOM*WEEKS*(1+DIM_PCT_TOM)^A12 -> 724.7295 | C12: =MIN(B12,FARMER_FIELD_HRS)*FARMER_RATE+MAX(0,B12-FARMER_FIELD_HRS)*TEMP_RATE -> 25082.109 | D12: =A12*FERTILIZER_PER_BED_TOM -> 4400 | E12: =C12+D12 -> 29482.109 | F12: =E12-E11 -> 7660.8594 | G12: =PRICE_PER_BED_TOM -> 8800 | H12: =IF(F12<=PRICE_PER_BED_TOM,1,0) -> 1 | I12: =I11*H12 -> 1 | K12: 5 | L12: =K12*HRS_PER_BED_WEEK_CAR*WEEKS*(1+DIM_PCT_CAR)^K12 -> 169.71123 | M12: =MIN(L12,FARMER_FIELD_HRS)*FARMER_RATE+MAX(0,L12-FARMER_FIELD_HRS)*TEMP_RATE -> 5892.7511 | N12: =K12*FERTILIZER_PER_BED_CAR -> 2200 | O12: =M12+N12 -> 8092.7511 | P12: =O12-O11 -> 1733.5307 | Q12: =PRICE_PER_BED_CAR -> 2094 | R12: =IF(P12<=PRICE_PER_BED_CAR,1,0) -> 1 | S12: =S11*R12 -> 1 | U12: 5 | V12: =U12*HRS_PER_BED_WEEK_MES*WEEKS*(1+DIM_PCT_MES)^U12 -> 239.41848 | W12: =MIN(V12,FARMER_FIELD_HRS)*FARMER_RATE+MAX(0,V12-FARMER_FIELD_HRS)*TEMP_RATE -> 8313.1418 | X12: =U12*FERTILIZER_PER_BED_MES -> 4400 | Y12: =W12+X12 -> 12713.142 | Z12: =Y12-Y11 -> 2624.7335 | AA12: =PRICE_PER_BED_MES -> 2700 | AB12: =IF(Z12<=PRICE_PER_BED_MES,1,0) -> 1 | AC12: =AC11*AB12 -> 1
A13: 6 | B13: =A13*HRS_PER_BED_WEEK_TOM*WEEKS*(1+DIM_PCT_TOM)^A13 -> 956.64294 | C13: =MIN(B13,FARMER_FIELD_HRS)*FARMER_RATE+MAX(0,B13-FARMER_FIELD_HRS)*TEMP_RATE -> 29108.384 | D13: =A13*FERTILIZER_PER_BED_TOM -> 5280 | E13: =C13+D13 -> 34388.384 | F13: =E13-E12 -> 4906.275 | G13: =PRICE_PER_BED_TOM -> 8800 | H13: =IF(F13<=PRICE_PER_BED_TOM,1,0) -> 1 | I13: =I12*H13 -> 1 | K13: 6 | L13: =K13*HRS_PER_BED_WEEK_CAR*WEEKS*(1+DIM_PCT_CAR)^K13 -> 208.74482 | M13: =MIN(L13,FARMER_FIELD_HRS)*FARMER_RATE+MAX(0,L13-FARMER_FIELD_HRS)*TEMP_RATE -> 7248.0839 | N13: =K13*FERTILIZER_PER_BED_CAR -> 2640 | O13: =M13+N13 -> 9888.0839 | P13: =O13-O12 -> 1795.3328 | Q13: =PRICE_PER_BED_CAR -> 2094 | R13: =IF(P13<=PRICE_PER_BED_CAR,1,0) -> 1 | S13: =S12*R13 -> 1 | U13: 6 | V13: =U13*HRS_PER_BED_WEEK_MES*WEEKS*(1+DIM_PCT_MES)^U13 -> 290.89346 | W13: =MIN(V13,FARMER_FIELD_HRS)*FARMER_RATE+MAX(0,V13-FARMER_FIELD_HRS)*TEMP_RATE -> 10100.467 | X13: =U13*FERTILIZER_PER_BED_MES -> 5280 | Y13: =W13+X13 -> 15380.467 | Z13: =Y13-Y12 -> 2667.3255 | AA13: =PRICE_PER_BED_MES -> 2700 | AB13: =IF(Z13<=PRICE_PER_BED_MES,1,0) -> 1 | AC13: =AC12*AB13 -> 1
A14: 7 | B14: =A14*HRS_PER_BED_WEEK_TOM*WEEKS*(1+DIM_PCT_TOM)^A14 -> 1227.6918 | C14: =MIN(B14,FARMER_FIELD_HRS)*FARMER_RATE+MAX(0,B14-FARMER_FIELD_HRS)*TEMP_RATE -> 33814.093 | D14: =A14*FERTILIZER_PER_BED_TOM -> 6160 | E14: =C14+D14 -> 39974.093 | F14: =E14-E13 -> 5585.7089 | G14: =PRICE_PER_BED_TOM -> 8800 | H14: =IF(F14<=PRICE_PER_BED_TOM,1,0) -> 1 | I14: =I13*H14 -> 1 | K14: 7 | L14: =K14*HRS_PER_BED_WEEK_CAR*WEEKS*(1+DIM_PCT_CAR)^K14 -> 249.62401 | M14: =MIN(L14,FARMER_FIELD_HRS)*FARMER_RATE+MAX(0,L14-FARMER_FIELD_HRS)*TEMP_RATE -> 8667.5003 | N14: =K14*FERTILIZER_PER_BED_CAR -> 3080 | O14: =M14+N14 -> 11747.5 | P14: =O14-O13 -> 1859.4164 | Q14: =PRICE_PER_BED_CAR -> 2094 | R14: =IF(P14<=PRICE_PER_BED_CAR,1,0) -> 1 | S14: =S13*R14 -> 1 | U14: 7 | V14: =U14*HRS_PER_BED_WEEK_MES*WEEKS*(1+DIM_PCT_MES)^U14 -> 343.6179 | W14: =MIN(V14,FARMER_FIELD_HRS)*FARMER_RATE+MAX(0,V14-FARMER_FIELD_HRS)*TEMP_RATE -> 11931.177 | X14: =U14*FERTILIZER_PER_BED_MES -> 6160 | Y14: =W14+X14 -> 18091.177 | Z14: =Y14-Y13 -> 2710.7097 | AA14: =PRICE_PER_BED_MES -> 2700 | AB14: =IF(Z14<=PRICE_PER_BED_MES,1,0) -> 0 | AC14: =AC13*AB14 -> 0
A15: 8 | B15: =A15*HRS_PER_BED_WEEK_TOM*WEEKS*(1+DIM_PCT_TOM)^A15 -> 1543.3839 | C15: =MIN(B15,FARMER_FIELD_HRS)*FARMER_RATE+MAX(0,B15-FARMER_FIELD_HRS)*TEMP_RATE -> 39294.86 | D15: =A15*FERTILIZER_PER_BED_TOM -> 7040 | E15: =C15+D15 -> 46334.86 | F15: =E15-E14 -> 6360.7668 | G15: =PRICE_PER_BED_TOM -> 8800 | H15: =IF(F15<=PRICE_PER_BED_TOM,1,0) -> 1 | I15: =I14*H15 -> 1 | K15: 8 | L15: =K15*HRS_PER_BED_WEEK_CAR*WEEKS*(1+DIM_PCT_CAR)^K15 -> 292.4167 | M15: =MIN(L15,FARMER_FIELD_HRS)*FARMER_RATE+MAX(0,L15-FARMER_FIELD_HRS)*TEMP_RATE -> 10153.357 | N15: =K15*FERTILIZER_PER_BED_CAR -> 3520 | O15: =M15+N15 -> 13673.357 | P15: =O15-O14 -> 1925.8572 | Q15: =PRICE_PER_BED_CAR -> 2094 | R15: =IF(P15<=PRICE_PER_BED_CAR,1,0) -> 1 | S15: =S14*R15 -> 1 | U15: 8 | V15: =U15*HRS_PER_BED_WEEK_MES*WEEKS*(1+DIM_PCT_MES)^U15 -> 397.615 | W15: =MIN(V15,FARMER_FIELD_HRS)*FARMER_RATE+MAX(0,V15-FARMER_FIELD_HRS)*TEMP_RATE -> 13806.076 | X15: =U15*FERTILIZER_PER_BED_MES -> 7040 | Y15: =W15+X15 -> 20846.076 | Z15: =Y15-Y14 -> 2754.8992 | AA15: =PRICE_PER_BED_MES -> 2700 | AB15: =IF(Z15<=PRICE_PER_BED_MES,1,0) -> 0 | AC15: =AC14*AB15 -> 0
A16: 9 | B16: =A16*HRS_PER_BED_WEEK_TOM*WEEKS*(1+DIM_PCT_TOM)^A16 -> 1909.9376 | C16: =MIN(B16,FARMER_FIELD_HRS)*FARMER_RATE+MAX(0,B16-FARMER_FIELD_HRS)*TEMP_RATE -> 45658.639 | D16: =A16*FERTILIZER_PER_BED_TOM -> 7920 | E16: =C16+D16 -> 53578.639 | F16: =E16-E15 -> 7243.7793 | G16: =PRICE_PER_BED_TOM -> 8800 | H16: =IF(F16<=PRICE_PER_BED_TOM,1,0) -> 1 | I16: =I15*H16 -> 1 | K16: 9 | L16: =K16*HRS_PER_BED_WEEK_CAR*WEEKS*(1+DIM_PCT_CAR)^K16 -> 337.193 | M16: =MIN(L16,FARMER_FIELD_HRS)*FARMER_RATE+MAX(0,L16-FARMER_FIELD_HRS)*TEMP_RATE -> 11708.09 | N16: =K16*FERTILIZER_PER_BED_CAR -> 3960 | O16: =M16+N16 -> 15668.09 | P16: =O16-O15 -> 1994.7329 | Q16: =PRICE_PER_BED_CAR -> 2094 | R16: =IF(P16<=PRICE_PER_BED_CAR,1,0) -> 1 | S16: =S15*R16 -> 1 | U16: 9 | V16: =U16*HRS_PER_BED_WEEK_MES*WEEKS*(1+DIM_PCT_MES)^U16 -> 452.90833 | W16: =MIN(V16,FARMER_FIELD_HRS)*FARMER_RATE+MAX(0,V16-FARMER_FIELD_HRS)*TEMP_RATE -> 15725.984 | X16: =U16*FERTILIZER_PER_BED_MES -> 7920 | Y16: =W16+X16 -> 23645.984 | Z16: =Y16-Y15 -> 2799.9075 | AA16: =PRICE_PER_BED_MES -> 2700 | AB16: =IF(Z16<=PRICE_PER_BED_MES,1,0) -> 0 | AC16: =AC15*AB16 -> 0
A17: 10 | B17: =A17*HRS_PER_BED_WEEK_TOM*WEEKS*(1+DIM_PCT_TOM)^A17 -> 2334.3682 | C17: =MIN(B17,FARMER_FIELD_HRS)*FARMER_RATE+MAX(0,B17-FARMER_FIELD_HRS)*TEMP_RATE -> 53027.226 | D17: =A17*FERTILIZER_PER_BED_TOM -> 8800 | E17: =C17+D17 -> 61827.226 | F17: =E17-E16 -> 8248.5865 | G17: =PRICE_PER_BED_TOM -> 8800 | H17: =IF(F17<=PRICE_PER_BED_TOM,1,0) -> 1 | I17: =I16*H17 -> 1 | K17: 10 | L17: =K17*HRS_PER_BED_WEEK_CAR*WEEKS*(1+DIM_PCT_CAR)^K17 -> 384.02536 | M17: =MIN(L17,FARMER_FIELD_HRS)*FARMER_RATE+MAX(0,L17-FARMER_FIELD_HRS)*TEMP_RATE -> 13334.214 | N17: =K17*FERTILIZER_PER_BED_CAR -> 4400 | O17: =M17+N17 -> 17734.214 | P17: =O17-O16 -> 2066.1237 | Q17: =PRICE_PER_BED_CAR -> 2094 | R17: =IF(P17<=PRICE_PER_BED_CAR,1,0) -> 1 | S17: =S16*R17 -> 1 | U17: 10 | V17: =U17*HRS_PER_BED_WEEK_MES*WEEKS*(1+DIM_PCT_MES)^U17 -> 509.52187 | W17: =MIN(V17,FARMER_FIELD_HRS)*FARMER_RATE+MAX(0,V17-FARMER_FIELD_HRS)*TEMP_RATE -> 17691.732 | X17: =U17*FERTILIZER_PER_BED_MES -> 8800 | Y17: =W17+X17 -> 26491.732 | Z17: =Y17-Y16 -> 2845.748 | AA17: =PRICE_PER_BED_MES -> 2700 | AB17: =IF(Z17<=PRICE_PER_BED_MES,1,0) -> 0 | AC17: =AC16*AB17 -> 0
A18: 11 | B18: =A18*HRS_PER_BED_WEEK_TOM*WEEKS*(1+DIM_PCT_TOM)^A18 -> 2824.5855 | C18: =MIN(B18,FARMER_FIELD_HRS)*FARMER_RATE+MAX(0,B18-FARMER_FIELD_HRS)*TEMP_RATE -> 61537.943 | D18: =A18*FERTILIZER_PER_BED_TOM -> 9680 | E18: =C18+D18 -> 71217.943 | F18: =E18-E17 -> 9390.7174 | G18: =PRICE_PER_BED_TOM -> 8800 | H18: =IF(F18<=PRICE_PER_BED_TOM,1,0) -> 0 | I18: =I17*H18 -> 0 | K18: 11 | L18: =K18*HRS_PER_BED_WEEK_CAR*WEEKS*(1+DIM_PCT_CAR)^K18 -> 432.9886 | M18: =MIN(L18,FARMER_FIELD_HRS)*FARMER_RATE+MAX(0,L18-FARMER_FIELD_HRS)*TEMP_RATE -> 15034.326 | N18: =K18*FERTILIZER_PER_BED_CAR -> 4840 | O18: =M18+N18 -> 19874.326 | P18: =O18-O17 -> 2140.1123 | Q18: =PRICE_PER_BED_CAR -> 2094 | R18: =IF(P18<=PRICE_PER_BED_CAR,1,0) -> 0 | S18: =S17*R18 -> 0 | U18: 11 | V18: =U18*HRS_PER_BED_WEEK_MES*WEEKS*(1+DIM_PCT_MES)^U18 -> 567.47999 | W18: =MIN(V18,FARMER_FIELD_HRS)*FARMER_RATE+MAX(0,V18-FARMER_FIELD_HRS)*TEMP_RATE -> 19704.166 | X18: =U18*FERTILIZER_PER_BED_MES -> 9680 | Y18: =W18+X18 -> 29384.166 | Z18: =Y18-Y17 -> 2892.4345 | AA18: =PRICE_PER_BED_MES -> 2700 | AB18: =IF(Z18<=PRICE_PER_BED_MES,1,0) -> 0 | AC18: =AC17*AB18 -> 0
A19: 12 | B19: =A19*HRS_PER_BED_WEEK_TOM*WEEKS*(1+DIM_PCT_TOM)^A19 -> 3389.5026 | C19: =MIN(B19,FARMER_FIELD_HRS)*FARMER_RATE+MAX(0,B19-FARMER_FIELD_HRS)*TEMP_RATE -> 71345.532 | D19: =A19*FERTILIZER_PER_BED_TOM -> 10560 | E19: =C19+D19 -> 81905.532 | F19: =E19-E18 -> 10687.589 | G19: =PRICE_PER_BED_TOM -> 8800 | H19: =IF(F19<=PRICE_PER_BED_TOM,1,0) -> 0 | I19: =I18*H19 -> 0 | K19: 12 | L19: =K19*HRS_PER_BED_WEEK_CAR*WEEKS*(1+DIM_PCT_CAR)^K19 -> 484.15998 | M19: =MIN(L19,FARMER_FIELD_HRS)*FARMER_RATE+MAX(0,L19-FARMER_FIELD_HRS)*TEMP_RATE -> 16811.11 | N19: =K19*FERTILIZER_PER_BED_CAR -> 5280 | O19: =M19+N19 -> 22091.11 | P19: =O19-O18 -> 2216.784 | Q19: =PRICE_PER_BED_CAR -> 2094 | R19: =IF(P19<=PRICE_PER_BED_CAR,1,0) -> 0 | S19: =S18*R19 -> 0 | U19: 12 | V19: =U19*HRS_PER_BED_WEEK_MES*WEEKS*(1+DIM_PCT_MES)^U19 -> 626.80744 | W19: =MIN(V19,FARMER_FIELD_HRS)*FARMER_RATE+MAX(0,V19-FARMER_FIELD_HRS)*TEMP_RATE -> 21764.147 | X19: =U19*FERTILIZER_PER_BED_MES -> 10560 | Y19: =W19+X19 -> 32324.147 | Z19: =Y19-Y18 -> 2939.981 | AA19: =PRICE_PER_BED_MES -> 2700 | AB19: =IF(Z19<=PRICE_PER_BED_MES,1,0) -> 0 | AC19: =AC18*AB19 -> 0
... A28: 21 | B28: =A28*HRS_PER_BED_WEEK_TOM*WEEKS*(1+DIM_PCT_TOM)^A28 -> 13986.472 | C28: =MIN(B28,FARMER_FIELD_HRS)*FARMER_RATE+MAX(0,B28-FARMER_FIELD_HRS)*TEMP_RATE -> 255320.7 | D28: =A28*FERTILIZER_PER_BED_TOM -> 18480 | E28: =C28+D28 -> 273800.7 | F28: =E28-E27 -> 33466.328 | G28: =PRICE_PER_BED_TOM -> 8800 | H28: =IF(F28<=PRICE_PER_BED_TOM,1,0) -> 0 | I28: =I27*H28 -> 0 | K28: 21 | L28: =K28*HRS_PER_BED_WEEK_CAR*WEEKS*(1+DIM_PCT_CAR)^K28 -> 1058.1366 | M28: =MIN(L28,FARMER_FIELD_HRS)*FARMER_RATE+MAX(0,L28-FARMER_FIELD_HRS)*TEMP_RATE -> 30870.426 | N28: =K28*FERTILIZER_PER_BED_CAR -> 9240 | O28: =M28+N28 -> 40110.426 | P28: =O28-O27 -> 1741.5052 | Q28: =PRICE_PER_BED_CAR -> 2094 | R28: =IF(P28<=PRICE_PER_BED_CAR,1,0) -> 1 | S28: =S27*R28 -> 0 | U28: 21 | V28: =U28*HRS_PER_BED_WEEK_MES*WEEKS*(1+DIM_PCT_MES)^U28 -> 1226.6692 | W28: =MIN(V28,FARMER_FIELD_HRS)*FARMER_RATE+MAX(0,V28-FARMER_FIELD_HRS)*TEMP_RATE -> 33796.341 | X28: =U28*FERTILIZER_PER_BED_MES -> 18480 | Y28: =W28+X28 -> 52276.341 | Z28: =Y28-Y27 -> 2144.5094 | AA28: =PRICE_PER_BED_MES -> 2700 | AB28: =IF(Z28<=PRICE_PER_BED_MES,1,0) -> 1 | AC28: =AC27*AB28 -> 0
A29: Standalone P = MC point | F29: =SUM(I8:I27) -> 10 | K29: Standalone P = MC point | P29: =SUM(S8:S27) -> 10 | U29: 22 | V29: =U29*HRS_PER_BED_WEEK_MES*WEEKS*(1+DIM_PCT_MES)^U29 -> 1301.1456 | W29: =MIN(V29,FARMER_FIELD_HRS)*FARMER_RATE+MAX(0,V29-FARMER_FIELD_HRS)*TEMP_RATE -> 35089.333 | X29: =U29*FERTILIZER_PER_BED_MES -> 19360 | Y29: =W29+X29 -> 54449.333 | Z29: =Y29-Y28 -> 2172.9921 | AA29: =PRICE_PER_BED_MES -> 2700 | AB29: =IF(Z29<=PRICE_PER_BED_MES,1,0) -> 1 | AC29: =AC28*AB29 -> 0
A30: First crossing: the run of MC <= P breaks here. | K30: First crossing: the run of MC <= P breaks here. | U30: 23 | V30: =U30*HRS_PER_BED_WEEK_MES*WEEKS*(1+DIM_PCT_MES)^U30 -> 1377.2922 | W30: =MIN(V30,FARMER_FIELD_HRS)*FARMER_RATE+MAX(0,V30-FARMER_FIELD_HRS)*TEMP_RATE -> 36411.323 | X30: =U30*FERTILIZER_PER_BED_MES -> 20240 | Y30: =W30+X30 -> 56651.323 | Z30: =Y30-Y29 -> 2201.9894 | AA30: =PRICE_PER_BED_MES -> 2700 | AB30: =IF(Z30<=PRICE_PER_BED_MES,1,0) -> 1 | AC30: =AC29*AB30 -> 0
A31: MC is not monotonic — a later q can fall back below price. The run column enforces "first", not "last". | K31: MC is not monotonic — a later q can fall back below price. The run column enforces "first", not "last". | U31: 24 | V31: =U31*HRS_PER_BED_WEEK_MES*WEEKS*(1+DIM_PCT_MES)^U31 -> 1455.1391 | W31: =MIN(V31,FARMER_FIELD_HRS)*FARMER_RATE+MAX(0,V31-FARMER_FIELD_HRS)*TEMP_RATE -> 37762.832 | X31: =U31*FERTILIZER_PER_BED_MES -> 21120 | Y31: =W31+X31 -> 58882.832 | Z31: =Y31-Y30 -> 2231.5095 | AA31: =PRICE_PER_BED_MES -> 2700 | AB31: =IF(Z31<=PRICE_PER_BED_MES,1,0) -> 1 | AC31: =AC30*AB31 -> 0
U32: 25 | V32: =U32*HRS_PER_BED_WEEK_MES*WEEKS*(1+DIM_PCT_MES)^U32 -> 1534.7171 | W32: =MIN(V32,FARMER_FIELD_HRS)*FARMER_RATE+MAX(0,V32-FARMER_FIELD_HRS)*TEMP_RATE -> 39144.393 | X32: =U32*FERTILIZER_PER_BED_MES -> 22000 | Y32: =W32+X32 -> 61144.393 | Z32: =Y32-Y31 -> 2261.5611 | AA32: =PRICE_PER_BED_MES -> 2700 | AB32: =IF(Z32<=PRICE_PER_BED_MES,1,0) -> 1 | AC32: =AC31*AB32 -> 0
U33: 26 | V33: =U33*HRS_PER_BED_WEEK_MES*WEEKS*(1+DIM_PCT_MES)^U33 -> 1616.0571 | W33: =MIN(V33,FARMER_FIELD_HRS)*FARMER_RATE+MAX(0,V33-FARMER_FIELD_HRS)*TEMP_RATE -> 40556.546 | X33: =U33*FERTILIZER_PER_BED_MES -> 22880 | Y33: =W33+X33 -> 63436.546 | Z33: =Y33-Y32 -> 2292.1528 | AA33: =PRICE_PER_BED_MES -> 2700 | AB33: =IF(Z33<=PRICE_PER_BED_MES,1,0) -> 1 | AC33: =AC32*AB33 -> 0
U34: 27 | V34: =U34*HRS_PER_BED_WEEK_MES*WEEKS*(1+DIM_PCT_MES)^U34 -> 1699.1908 | W34: =MIN(V34,FARMER_FIELD_HRS)*FARMER_RATE+MAX(0,V34-FARMER_FIELD_HRS)*TEMP_RATE -> 41999.84 | X34: =U34*FERTILIZER_PER_BED_MES -> 23760 | Y34: =W34+X34 -> 65759.84 | Z34: =Y34-Y33 -> 2323.2935 | AA34: =PRICE_PER_BED_MES -> 2700 | AB34: =IF(Z34<=PRICE_PER_BED_MES,1,0) -> 1 | AC34: =AC33*AB34 -> 0
U35: 28 | V35: =U35*HRS_PER_BED_WEEK_MES*WEEKS*(1+DIM_PCT_MES)^U35 -> 1784.1503 | W35: =MIN(V35,FARMER_FIELD_HRS)*FARMER_RATE+MAX(0,V35-FARMER_FIELD_HRS)*TEMP_RATE -> 43474.832 | X35: =U35*FERTILIZER_PER_BED_MES -> 24640 | Y35: =W35+X35 -> 68114.832 | Z35: =Y35-Y34 -> 2354.992 | AA35: =PRICE_PER_BED_MES -> 2700 | AB35: =IF(Z35<=PRICE_PER_BED_MES,1,0) -> 1 | AC35: =AC34*AB35 -> 0
U36: 29 | V36: =U36*HRS_PER_BED_WEEK_MES*WEEKS*(1+DIM_PCT_MES)^U36 -> 1870.9683 | W36: =MIN(V36,FARMER_FIELD_HRS)*FARMER_RATE+MAX(0,V36-FARMER_FIELD_HRS)*TEMP_RATE -> 44982.089 | X36: =U36*FERTILIZER_PER_BED_MES -> 25520 | Y36: =W36+X36 -> 70502.089 | Z36: =Y36-Y35 -> 2387.2574 | AA36: =PRICE_PER_BED_MES -> 2700 | AB36: =IF(Z36<=PRICE_PER_BED_MES,1,0) -> 1 | AC36: =AC35*AB36 -> 0
U37: 30 | V37: =U37*HRS_PER_BED_WEEK_MES*WEEKS*(1+DIM_PCT_MES)^U37 -> 1959.678 | W37: =MIN(V37,FARMER_FIELD_HRS)*FARMER_RATE+MAX(0,V37-FARMER_FIELD_HRS)*TEMP_RATE -> 46522.188 | X37: =U37*FERTILIZER_PER_BED_MES -> 26400 | Y37: =W37+X37 -> 72922.188 | Z37: =Y37-Y36 -> 2420.0991 | AA37: =PRICE_PER_BED_MES -> 2700 | AB37: =IF(Z37<=PRICE_PER_BED_MES,1,0) -> 1 | AC37: =AC36*AB37 -> 0
U38: 31 | V38: =U38*HRS_PER_BED_WEEK_MES*WEEKS*(1+DIM_PCT_MES)^U38 -> 2050.3131 | W38: =MIN(V38,FARMER_FIELD_HRS)*FARMER_RATE+MAX(0,V38-FARMER_FIELD_HRS)*TEMP_RATE -> 48095.714 | X38: =U38*FERTILIZER_PER_BED_MES -> 27280 | Y38: =W38+X38 -> 75375.714 | Z38: =Y38-Y37 -> 2453.5262 | AA38: =PRICE_PER_BED_MES -> 2700 | AB38: =IF(Z38<=PRICE_PER_BED_MES,1,0) -> 1 | AC38: =AC37*AB38 -> 0
U39: Standalone P = MC point | Z39: =SUM(AC8:AC37) -> 6
U40: First crossing: the run of MC <= P breaks here.
U41: MC is not monotonic — a later q can fall back below price. The run column enforces "first", not "last".

Sheet Checks
A1: Validation rules — Section 4
A2: Run Solver first (Optimization sheet), then read this sheet.
A4: Check | B4: Required | C4: Actual | D4: Status | E4: Note
A5: Optimal mix — tomato beds | B5: =10 -> 10 | C5: =BEDS_TOMATO -> 10 | D5: =IF(C5=B5,"PASS","FAIL") -> PASS | E5: Must match exactly
A6: Optimal mix — carrot beds | B6: =20 -> 20 | C6: =BEDS_CARROT -> 20 | D6: =IF(C6=B6,"PASS","FAIL") -> PASS | E6: Must match exactly
A7: Optimal mix — mesclun beds | B7: =30 -> 30 | C7: =BEDS_MESCLUN -> 30 | D7: =IF(C7=B7,"PASS","FAIL") -> PASS | E7: Must match exactly
A8: Total beds planted | B8: =60 -> 60 | C8: =BEDS_TOMATO+BEDS_CARROT+BEDS_MESCLUN -> 60 | D8: =IF(C8=B8,"PASS","FAIL") -> PASS | E8: 60 of the 64 available
A9: Season profit | B9: =42762 -> 42762 | C9: =SEASON_PROFIT -> 42761.665 | D9: =IF(ABS(C9-B9)<=5,"PASS","FAIL") -> PASS | E9: Passes within +/- $5
A10: Standalone P = MC — tomatoes | B10: =10 -> 10 | C10: =PMC_TOM -> 10 | D10: =IF(ABS(C10-B10)<=1,"PASS","FAIL") -> PASS | E10: Passes within +/- 1 bed
A11: Standalone P = MC — carrots | B11: =10 -> 10 | C11: =PMC_CAR -> 10 | D11: =IF(ABS(C11-B11)<=1,"PASS","FAIL") -> PASS | E11: Passes within +/- 1 bed
A12: Standalone P = MC — mesclun | B12: =6 -> 6 | C12: =PMC_MES -> 6 | D12: =IF(ABS(C12-B12)<=1,"PASS","FAIL") -> PASS | E12: Passes within +/- 1 bed
A13: Hand check — LABOR_HRS(1) tomatoes | B13: =99 -> 99 | C13: =HAND_CHECK_Q1 -> 99 | D13: =IF(ABS(C13-B13)<=0.01,"PASS","FAIL") -> PASS | E13: 1 x 2.50 x 36 x 1.10
A14: Blended-rate allocation equals total labor cost | B14: =CostStructure!B18 -> 104118.34 | C14: =CostStructure!B26 -> 104118.34 | D14: =IF(ABS(C14-B14)<=0.01,"PASS","FAIL") -> PASS | E14: Labor is never double counted
A15: Temp workers required at most 4 | B15: =MAX_TEMPS -> 4 | C15: =TEMPS_REQUIRED -> 4 | D15: =IF(C15<=B15,"PASS","FAIL") -> PASS | E15: Headcount, rounded up
A16: All constraint checks pass | B16: ="PASS" -> PASS | C16: =CONSTRAINTS_ALL -> PASS | D16: =IF(C16=B16,"PASS","FAIL") -> PASS | E16: Optimization sheet, D19
A17: Hand check — LABOR_HRS(10) tomatoes | B17: =2334.368214 -> 2334.3682 | C17: =MCSchedules!B17 -> 2334.3682 | D17: =IF(ABS(C17-B17)<=0.001,"PASS","FAIL") -> PASS | E17: Second anchor. A flat (1+DIM_PCT) instead of compounding returns 990 here but still 99 at q=1.
A18: Farm Profit Lab — MC of the 7th tomato bed | B18: =5586 -> 5586 | C18: =MCSchedules!F14 -> 5585.7089 | D18: =IF(ABS(C18-B18)<=1,"PASS","FAIL") -> PASS | E18: Lab totals run $20,000 higher (fixed costs it includes); compare marginal, not total.
A19: Shadow price — carrot bed cap | B19: =352 -> 352 | C19: =SHADOW_CAR -> 352.49475 | D19: =IF(ABS(C19-B19)<=5,"PASS","FAIL") -> PASS | E19: Passes within +/- $5
A20: Shadow price — mesclun bed cap | B20: =246 -> 246 | C20: =SHADOW_MES -> 246.4738 | D20: =IF(ABS(C20-B20)<=5,"PASS","FAIL") -> PASS | E20: Passes within +/- $5
A21: Shadow price equals PRICE - MC(cap+1) — carrots | B21: =PRICE_PER_BED_CAR-MCSchedules!P28 -> 352.49475 | C21: =SHADOW_CAR -> 352.49475 | D21: =IF(ABS(C21-B21)<=1,"PASS","FAIL") -> PASS | E21: Two routes through the model, no shared formula
A22: Shadow price equals PRICE - MC(cap+1) — mesclun | B22: =PRICE_PER_BED_MES-MCSchedules!Z38 -> 246.4738 | C22: =SHADOW_MES -> 246.4738 | D22: =IF(ABS(C22-B22)<=1,"PASS","FAIL") -> PASS | E22: Two routes through the model, no shared formula
A24: Structural rules — verified by inspection, not by formula
A25: - No error cells anywhere in the workbook — no #REF!, #DIV/0!, #NAME?, #VALUE! or #N/A.
A26: - Every calculated cell contains a formula referencing named ranges. No pasted values.
A27: - Every input is a real named range carrying the unit stated on the Inputs sheet.
A28: - Spot-check: click any cell on Cost structure or MC schedules and confirm the formula bar shows a formula.
A30: Solver path-dependence — record both runs here during the audit
A31: Starting point | B31: Tomatoes | C31: Carrots | D31: Mesclun | E31: Season profit
A32: 0 / 0 / 0 | B32: 10 | C32: 20 | D32: 30 | E32: =SEASON_PROFIT -> 42761.665
A33: 20 / 0 / 0 | B33: 10 | C33: 20 | D33: 30 | E33: =SEASON_PROFIT -> 42761.665
A35: Both starting points converged on the same answer: 10 / 20 / 30, season profit $42,762.
A36: No path dependence observed. Agreement across two starts is evidence the optimum is global,
A37: not the first summit GRG Nonlinear happened to reach. Solver settings were identical in both runs;
A38: only the contents of B5:B7 differed.
